Workbook

Sheet Screening
A1: ID | B1: Database | C1: Title | D1: Authors | E1: Year | F1: Source | G1: Document type | H1: DOI | I1: FL | J1: DP | K1: XAI | L1: KG | M1: DL | N1: Decision | O1: Reason | P1: Closest to this study | Q1: Author check (Agree/Disagree) | R1: Author notes
A2: 1 | B2: Scopus | C2: A Systematic Review of Intrusion Detection Systems, Challenges, and Emerging AI-Driven Solutions | D2: Reddy A.S.; Shanthi S.G.; Reddy K.P. | E2: 2026 | F2: GSEACT 2026 - 2026 IEEE Global Symposium on Emerging and Communication Technologies | G2: Conference paper | H2: 10.1109/GSEACT68539.2026.11620510 | I2: Y | K2: Y | M2: Y | N2: E1 | O2: Review, survey, or overview (kept as background)
A3: 2 | B3: Scopus | C3: Cybersecurity in Smart Grids using Machine Learning: A Systematic Literature Review | D3: Nelufule N.; Mudau C.; Nkwe B.; Chishiri S.; Mncwango L.; Mutenwa M. | E3: 2025 | F3: Proceedings of 6th International Conference on IoT Based Control Networks and Intelligent Systems, ICICNIS 2025 | G3: Conference paper | H3: 10.1109/ICICNIS66685.2025.11315506 | I3: Y | K3: Y | M3: Y | N3: E1 | O3: Review, survey, or overview (kept as background)
A4: 3 | B4: Scopus | C4: SAFENET AI- AI -Powered Intrusion Prevention System | D4: Wankhade A.; Wankhede T.; Yadav A.; Bhimanpallewar R.N. | E4: 2025 | F4: 2025 IEEE Pune Section International Conference, PuneCon 2025 | G4: Conference paper | H4: 10.1109/PuneCon67554.2025.11377588 | I4: Y | K4: Y | M4: Y | N4: INCLUDE | O4: Meets all inclusion criteria at title/abstract level
A5: 4 | B5: Scopus | C5: A Federated GAN-Augmented Explainable Deep Learning Framework for IoT Intrusion Detection | D5: Ramya S.P.; Kanimozhi K.V.; Sreesubha S.; Agoramoorthy M.; Loganayagi S. | E5: 2026 | F5: Proceedings of the 4th International Conference on Intelligent Data Communication Technologies and Internet of Things, IDCioT 2026 | G5: Conference paper | H5: 10.1109/IDCIoT67589.2026.11455702 | I5: Y | K5: Y | M5: Y | N5: INCLUDE | O5: Meets all inclusion criteria at title/abstract level
A6: 5 | B6: Scopus | C6: A Federated Attention-Enhanced Graph Neural Network Framework for Real-Time Intrusion Detection in Edge Computing Environments | D6: Kumar A.; Kaur S.; Sachdeva R.; Kaur K. | E6: 2025 | F6: 2025 IEEE 4th International Conference for Advancement in Technology, ICONAT 2025 | G6: Conference paper | H6: 10.1109/ICONAT66879.2025.11362512 | I6: Y | K6: Y | M6: Y | N6: INCLUDE | O6: Meets all inclusion criteria at title/abstract level
A7: 6 | B7: Scopus | C7: Smart Grid Intrusion Detection for IEC 60870-5-104 With Feature Optimization, Privacy Protection, and Honeypot-Firewall Integration | D7: Mrudula P.S.; Raj R.D.A.; Pallakonda A.; Reddy Y.R.A.; Prakasha K.K.; Anandkumar V. | E7: 2025 | F7: IEEE Access | G7: Article | H7: 10.1109/ACCESS.2025.3590151 | I7: Y | J7: Y | K7: Y | N7: INCLUDE | O7: Meets all inclusion criteria at title/abstract level
A8: 7 | B8: Scopus | C8: Federated learning explainable deep learning framework for enhanced internet of medical things security | D8: Saheed Y.K.; Chukwuere J.E. | E8: 2026 | F8: Discover Artificial Intelligence | G8: Article | H8: 10.1007/s44163-026-02034-0 | I8: Y | K8: Y | M8: Y | N8: INCLUDE | O8: Meets all inclusion criteria at title/abstract level
A9: 8 | B9: Scopus | C9: A Review of the Progressive Odyssey of AI-Driven Intrusion Detection Within Embedded Systems | D9: Alansari A.; Alfaqeer R.; Hammoudeh M. | E9: 2024 | F9: Lecture Notes in Computer Science (including subseries Lecture Notes in Artificial Intelligence and Lecture Notes in Bioinformatics) | G9: Conference paper | H9: 10.1007/978-3-031-61231-2_1 | I9: Y | J9: Y | K9: Y | M9: Y | N9: E1 | O9: Review article
A10: 9 | B10: Scopus | C10: Towards Transparent AI-Powered Cybersecurity in Financial Systems: The Deployment of Federated Learning and Explainable AI in the CaixaBank pilot | D10: Karampasi A.; Radoglou-Grammatikis P.; Pawlicki M.; Choras R.; De Pozuelo R.M.; Sarigiannidis P.; Puchalski D.; Pawlicka A.; Kozik R.; Choras M. | E10: 2024 | F10: IEEE International Conference on Data Mining Workshops, ICDMW | G10: Conference paper | H10: 10.1109/ICDMW65004.2024.00041 | I10: Y | K10: Y | N10: INCLUDE | O10: Meets all inclusion criteria at title/abstract level
A11: 10 | B11: Scopus | C11: Quantum Federated Learning for DoS Attack Detection and Privacy Preserving of VANET: A Novel Hybrid Machine Learning Approach | D11: Baihan A.; Ullah Z.; Irshad A.; Shafiq M.; Choi J.-G.; Amoon M. | E11: 2026 | F11: Transactions on Emerging Telecommunications Technologies | G11: Article | H11: 10.1002/ett.70375 | I11: Y | K11: Y | N11: INCLUDE | O11: Meets all inclusion criteria at title/abstract level
A12: 11 | B12: Scopus | C12: Towards Explainable and Distributed Intrusion Detection in IoTs: A Federated Learning-Based Approach | D12: Mutlu G.; Rihani N.; Sahingoz O.K. | E12: 2025 | F12: 2025 Innovations in Intelligent Systems and Applications Conference, ASYU 2025 | G12: Conference paper | H12: 10.1109/ASYU67174.2025.11208321 | I12: Y | K12: Y | M12: Y | N12: INCLUDE | O12: Meets all inclusion criteria at title/abstract level
A13: 12 | B13: Scopus | C13: XDFC-IDS: An explainable decentralized federated class-incremental fusion framework for intrusion detection | D13: Huu Quyen N.; Pham V.-H.; The Duy P. | E13: 2026 | F13: Expert Systems with Applications | G13: Article | H13: 10.1016/j.eswa.2026.133417 | I13: Y | K13: Y | M13: Y | N13: INCLUDE | O13: Meets all inclusion criteria at title/abstract level
A14: 13 | B14: Scopus | C14: Privacy-Preserving Federated and Explainable BigSecure-IoT Architecture for Robust Intrusion Detection in IoT Big-Data Platforms | D14: Girisha C.; Saritha S.J. | E14: 2026 | F14: Proceedings of 4th International Conference on Electronics and Renewable Systems, ICEARS 2026 | G14: Conference paper | H14: 10.1109/ICEARS67481.2026.11416610 | I14: Y | K14: Y | M14: Y | N14: INCLUDE | O14: Meets all inclusion criteria at title/abstract level
A15: 14 | B15: Scopus | C15: Creating a Trustworthy IDS for Cyber Physical Systems | D15: Cardenas M.C.G.; Cooper A.; Roy K.; Mason J. | E15: 2025 | F15: icABCD 2025 - Proceedings of the 2025 International Conference on Ai, Big Data, Computing and Data Communication Systems | G15: Conference paper | H15: 10.1145/3759023.3759118 | I15: Y | K15: Y | M15: Y | N15: INCLUDE | O15: Meets all inclusion criteria at title/abstract level
A16: 15 | B16: Scopus | C16: GBOA_SR-ShuffleNet: an explainable federated learning framework for privacy-preserving intrusion detection in IoT | D16: Jacob S.L.; Sultana H.P. | E16: 2026 | F16: Scientific Reports | G16: Article | H16: 10.1038/s41598-026-56215-z | I16: Y | K16: Y | N16: INCLUDE | O16: Meets all inclusion criteria at title/abstract level
A17: 16 | B17: Scopus | C17: EX-DFL: An Explainable Deep Federated-based Intrusion Detection System for Industrial IoT | D17: Attique D.; Wang H.; Wang P.; Javeed D.; Adil M. | E17: 2024 | F17: Proceedings - 21st International Joint Conference on Computer Science and Software Engineering, JCSSE 2024 | G17: Conference paper | H17: 10.1109/JCSSE61278.2024.10613665 | I17: Y | K17: Y | M17: Y | N17: INCLUDE | O17: Meets all inclusion criteria at title/abstract level
A18: 17 | B18: Scopus | C18: Hybrid Ai and Cryptographic Approaches for Secure and Explainable IoT-Based Cyber-Physical Systems | D18: Chaturbhuj S.; Meshram V.S.; Mankar J.B.; Yadav S.; Modani D.G.; Panadiwal H. | E18: 2026 | F18: 6th International Conference on Recent Trends in Computer Science and Technology, ICRTCST 2026 - Proceedings | G18: Conference paper | H18: 10.1109/ICRTCST68392.2026.11545233 | I18: Y | K18: Y | M18: Y | N18: INCLUDE | O18: Meets all inclusion criteria at title/abstract level
A19: 18 | B19: Scopus | C19: Cybersecurity Fortification in Edge Computing through the Synergy of Deep Learning | D19: Karyemsetty N.; Narasimha P.B.; Tejaswi M.P.; Sivaji V.N.; Kamal C.L.V.; Samatha B. | E19: 2023 | F19: 7th International Conference on I-SMAC (IoT in Social, Mobile, Analytics and Cloud), I-SMAC 2023 - Proceedings | G19: Conference paper | H19: 10.1109/I-SMAC58438.2023.10290400 | I19: Y | K19: Y | M19: Y | N19: INCLUDE | O19: Meets all inclusion criteria at title/abstract level
A20: 19 | B20: Scopus | C20: Machine Learning Techniques for Real-Time Anomaly Detection in Network Traffic | D20: Chhillar K.; Kushwaha M.; Saxena A.; Singh S. | E20: 2025 | F20: 2025 IEEE 7th International Conference on Computing, Communication and Automation, ICCCA 2025 | G20: Conference paper | H20: 10.1109/ICCCA66364.2025.11325729 | I20: Y | K20: Y | M20: Y | N20: INCLUDE | O20: Meets all inclusion criteria at title/abstract level
A21: 20 | B21: Scopus | C21: Explanation stability assessment for federated explainable intrusion detection in wireless sensor networks | D21: A. H.S.; P. D. | E21: 2026 | F21: Array | G21: Article | H21: 10.1016/j.array.2026.101114 | I21: Y | J21: Y | K21: Y | N21: INCLUDE | O21: Meets all inclusion criteria at title/abstract level | P21: Yes
A22: 21 | B22: Scopus | C22: Graph–Time IoT IDS: Requirement-Aligned Impact Evaluation | D22: Dubey K.; Batra I.; Bajpai A.; Malik A.; Alshara M.A.; Jan T.; Ahmad N.; Khalil R.A. | E22: 2026 | F22: Engineering Reports | G22: Article | H22: 10.1002/eng2.70975 | J22: Y | K22: Y | M22: Y | N22: INCLUDE | O22: Meets all inclusion criteria at title/abstract level
A23: 22 | B23: Scopus | C23: AI-Driven Defense-in-Depth: A Systematic Review of SOC Maturity Models and DDoS Mitigation | D23: Antoniou G. | E23: 2025 | F23: CEUR Workshop Proceedings | G23: Conference paper | I23: Y | K23: Y | N23: E1 | O23: Review, survey, or overview (kept as background)
A24: 23 | B24: Scopus | C24: XFedGraph-Hunter: An Interpretable Federated Learning Framework for Hunting Advanced Persistent Threat in Provenance Graph | D24: Son N.D.H.; Thi H.T.; Duy P.T.; Pham V.-H. | E24: 2023 | F24: Lecture Notes in Computer Science | G24: Conference paper | H24: 10.1007/978-981-99-7032-2_32 | I24: Y | K24: Y | M24: Y | N24: INCLUDE | O24: Meets all inclusion criteria at title/abstract level
A25: 24 | B25: Scopus | C25: GeoForensic-AI: A Lightweight and Explainable Forensic AI Framework for Modern Digital Ecosystems | D25: Manivannan A.; Amalanathan A. | E25: 2026 | F25: IEEE Access | G25: Article | H25: 10.1109/ACCESS.2026.3686828 | I25: Y | J25: Y | K25: Y | M25: Y | N25: E2 | O25: Digital forensics framework, not an intrusion detector
A26: 25 | B26: Scopus | C26: A semi-supervised soft prototype-based autonomous fuzzy ensemble system for network intrusion detection | D26: Gu X.; Howells G.; Yuan H. | E26: 2025 | F26: Applied Soft Computing | G26: Article | H26: 10.1016/j.asoc.2025.112719 | K26: Y | M26: Y | N26: E3 | O26: Federated learning or differential privacy not part of the method
A27: 26 | B27: Scopus | C27: Real-Time Cyber Threat Intelligence Detection and Response Using Deep Learning for Advanced Threat Classification | D27: Sriram Muganthan G.; Srivignesh L.; Rajashree S.; Miriam A.J.; Muneera M.N.; Santhanakrishnan | E27: 2026 | F27: 2026 IEEE 3rd International Conference on Emerging Trends in Engineering and Medical Sciences, ICETEMS 2025 | G27: Conference paper | H27: 10.1109/ICETEMS66917.2026.11469514 | I27: Y | K27: Y | M27: Y | N27: INCLUDE | O27: Meets all inclusion criteria at title/abstract level
A28: 27 | B28: Scopus | C28: FedDTKG: Federated Temporal Graph Learning with Adaptive Loss for Robust 5G Attack Detection under Extreme Class Imbalance | D28: Sheikhi S.; Loven L.; Pirttikangas S.; Kostakos P. | E28: 2025 | F28: MSWiM 2025 - 27th International Conference on Modeling, Analysis and Simulation of Wireless and Mobile Systems | G28: Conference paper | H28: 10.1109/MSWiM67937.2025.11308990 | I28: Y | L28: Y | M28: Y | N28: INCLUDE | O28: Meets all inclusion criteria at title/abstract level
A29: 28 | B29: Scopus | C29: Explainable Federated Learning for Botnet Detection in IoT Networks | D29: Kalakoti R.; Bahsi H.; Nomm S. | E29: 2024 | F29: Proceedings of the 2024 IEEE International Conference on Cyber Security and Resilience, CSR 2024 | G29: Conference paper | H29: 10.1109/CSR61664.2024.10679348 | I29: Y | K29: Y | M29: Y | N29: INCLUDE | O29: Meets all inclusion criteria at title/abstract level
A30: 29 | B30: Scopus | C30: Evaluation of Applying Federated Learning to Distributed Intrusion Detection Systems Through Explainable AI | D30: Oki A.; Ogawa Y.; Ota K.; Dong M. | E30: 2024 | F30: IEEE Networking Letters | G30: Article | H30: 10.1109/LNET.2024.3465516 | I30: Y | K30: Y | M30: Y | N30: INCLUDE | O30: Meets all inclusion criteria at title/abstract level
A31: 30 | B31: Scopus | C31: Generative AI–Guided Sentinel for Self-Optimizing Federated Cybersecurity and Intelligent Threat Detection; [生成式人工智能引导的哨兵系统，用于自我优化的联邦网络安全与智能威胁检测] | D31: Rokaya A.; Rishat M.A.S.A.; Sudhanshu S.; Singh A.; Naizheng B. | E31: 2025 | F31: Hunan Daxue Xuebao/Journal of Hunan University Natural Sciences | G31: Article | H31: 10.55463/ISSN.1674-2974.52.12.1 | I31: Y | K31: Y | N31: INCLUDE | O31: Meets all inclusion criteria at title/abstract level
A32: 31 | B32: Scopus | C32: Interpretable Federated Learning Model for Cyber Intrusion Detection in Smart Cities with Privacy-Preserving Feature Selection | D32: Farooq M.S.; Saleem M.; Khan M.A.; Khan M.F.; Siddiqui S.Y.; Aslam M.S.; Adnan K.M. | E32: 2025 | F32: Computers, Materials and Continua | G32: Article | H32: 10.32604/cmc.2025.069641 | I32: Y | K32: Y | N32: INCLUDE | O32: Meets all inclusion criteria at title/abstract level
A33: 32 | B33: Scopus | C33: AI-Powered Defense Against Advanced Persistent Threats (APTs): Techniques, Case Studies, and Future Research Directions | D33: Prajwalasimha S.N.; Shelke N.; Saini D.K.J.B.; Pimpalkar A.; Kumar G.H.; Shivamma D. | E33: 2025 | F33: Proceedings of 3rd International Conference on Sustainable Computing and Data Communication Systems, ICSCDS 2025 | G33: Conference paper | H33: 10.1109/ICSCDS65426.2025.11166697 | I33: Y | K33: Y | M33: Y | N33: E4 | O33: No experimental evaluation reported in the abstract
A34: 33 | B34: Scopus | C34: Intrusion Detection Explainability by Ensemble Learning with a Case Study | D34: Manai E.; Mejri M.; Fattahi J. | E34: 2024 | F34: 10th 2024 International Conference on Control, Decision and Information Technologies, CoDIT 2024 | G34: Conference paper | H34: 10.1109/CoDIT62066.2024.10708602 | K34: Y | N34: E3 | O34: Federated learning or differential privacy not part of the method
A35: 34 | B35: Scopus | C35: LLM-Driven Security and Resilience in 6G Mission-Critical Communication Networks | D35: Sai S.; Arora B.; Suri V.; Chamola V.; Gurusamy M. | E35: 2026 | F35: IEEE Open Journal of the Communications Society | G35: Article | H35: 10.1109/OJCOMS.2026.3717648 | I35: Y | K35: Y | N35: E4 | O35: No experimental evaluation reported in the abstract
A36: 35 | B36: Scopus | C36: Ai-Driven Cybersecurity Defense for Military Networks | D36: Bose S.S.C.; Shanmugapriya V.; Mahadev N.; Pyingkodi M.; Natarajan R.; Thangarasu N. | E36: 2025 | F36: Proceedings of IEEE International Conference for Women in Innovation, Technology and Entrepreneurship, ICWITE 2025 | G36: Conference paper | H36: 10.1109/ICWITE64848.2025.11307120 | I36: Y | K36: Y | N36: INCLUDE | O36: Meets all inclusion criteria at title/abstract level
A37: 36 | B37: Scopus | C37: Unified Framework for Outlier Detection Using Ensemble-Based Learning Techniques | D37: Dahiya R.; Dahiya V.K.; Agarwal N.; Jain H.; Kumar A.P.; Kumar Singh A. | E37: 2025 | F37: 2025 2nd International Conference on Computational Intelligence, Communication Technology and Networking, CICTN 2025 | G37: Conference paper | H37: 10.1109/CICTN64563.2025.10932383 | I37: Y | K37: Y | M37: Y | N37: INCLUDE | O37: Meets all inclusion criteria at title/abstract level
A38: 37 | B38: Scopus | C38: FL-TSA-TabNet: Federated Tabular Network for Intrusion Detection | D38: Archana J.; Kamalakkannan S. | E38: 2025 | F38: Proceedings of the 4th International Conference on Innovative Mechanisms for Industry Applications, ICIMIA 2025 | G38: Conference paper | H38: 10.1109/ICIMIA67127.2025.11200893 | I38: Y | K38: Y | M38: Y | N38: INCLUDE | O38: Meets all inclusion criteria at title/abstract level
A39: 38 | B39: Scopus | C39: A Comprehensive Review on Machine Learning Approaches for Zero-Day Attack Detection | D39: Ahmed Z.; Jayakesh G.; Azeem S. | E39: 2026 | F39: International Conference on Innovations in Communication, Geoscience and Robotics, ICICGR 2026 | G39: Conference paper | H39: 10.1109/ICICGR68236.2026.11600199 | I39: Y | K39: Y | N39: E1 | O39: Review, survey, or overview (kept as background)
A40: 39 | B40: Scopus | C40: Federated Learning-Based Intrusion Detection for Resource-Constrained IoT Devices Using Lightweight Neural Networks | D40: Saxena N.; Verma S.; Shubneet; Rella B.P.R.; Yadav A.R.; Talwandi N.S. | E40: 2026 | F40: Lecture Notes in Networks and Systems | G40: Conference paper | H40: 10.1007/978-3-032-25617-1_11 | I40: Y | J40: Y | K40: Y | M40: Y | N40: INCLUDE | O40: Meets all inclusion criteria at title/abstract level
...

Sheet Summary
A1: PRISMA-style counts (Scopus 30 Sep 2026; IEEE Xplore and Web of Science 1 Oct 2026)
A2: Stage | B2: Scopus | C2: IEEE Xplore | D2: Web of Science | E2: Total | F2: Note
A3: Records identified | B3: 245 | C3: 363 | D3: 95 | E3: =B3+C3+D3 -> 703 | F3: Typed by hand from the database interfaces
A4: Not exported | B4: 2 | C4: 0 | D4: 0 | E4: =B4+C4+D4 -> 2
A5: Outside 2019-2026 | B5: 0 | C5: 0 | D5: 1 | E5: =B5+C5+D5 -> 1 | F5: WoS record dated 2027
A6: Duplicates removed (found in an earlier database) | B6: 0 | C6: 125 | D6: 87 | E6: =B6+C6+D6 -> 212 | F6: Matched by DOI or normalised title
A7: Records screened | B7: =COUNTIF(Screening!B2:B489,"Scopus") -> 243 | C7: =COUNTIF(Screening!B2:B489,"IEEE Xplore") -> 238 | D7: =COUNTIF(Screening!B2:B489,"Web of Science") -> 7 | E7: =B7+C7+D7 -> 488
A8: Excluded E1: review or survey | B8: =COUNTIFS(Screening!B2:B489,"Scopus",Screening!N2:N489,"E1") -> 38 | C8: =COUNTIFS(Screening!B2:B489,"IEEE Xplore",Screening!N2:N489,"E1") -> 48 | D8: =COUNTIFS(Screening!B2:B489,"Web of Science",Screening!N2:N489,"E1") -> 4 | E8: =B8+C8+D8 -> 90
A9: Excluded E2: not intrusion detection | B9: =COUNTIFS(Screening!B2:B489,"Scopus",Screening!N2:N489,"E2") -> 4 | C9: =COUNTIFS(Screening!B2:B489,"IEEE Xplore",Screening!N2:N489,"E2") -> 3 | D9: =COUNTIFS(Screening!B2:B489,"Web of Science",Screening!N2:N489,"E2") -> 0 | E9: =B9+C9+D9 -> 7
A10: Excluded E3: no FL or DP in the method | B10: =COUNTIFS(Screening!B2:B489,"Scopus",Screening!N2:N489,"E3") -> 10 | C10: =COUNTIFS(Screening!B2:B489,"IEEE Xplore",Screening!N2:N489,"E3") -> 103 | D10: =COUNTIFS(Screening!B2:B489,"Web of Science",Screening!N2:N489,"E3") -> 0 | E10: =B10+C10+D10 -> 113
A11: Excluded E4: no experimental evaluation | B11: =COUNTIFS(Screening!B2:B489,"Scopus",Screening!N2:N489,"E4") -> 13 | C11: =COUNTIFS(Screening!B2:B489,"IEEE Xplore",Screening!N2:N489,"E4") -> 13 | D11: =COUNTIFS(Screening!B2:B489,"Web of Science",Screening!N2:N489,"E4") -> 0 | E11: =B11+C11+D11 -> 26
A12: Excluded E5: neither XAI nor ontology/KG | B12: =COUNTIFS(Screening!B2:B489,"Scopus",Screening!N2:N489,"E5") -> 0 | C12: =COUNTIFS(Screening!B2:B489,"IEEE Xplore",Screening!N2:N489,"E5") -> 18 | D12: =COUNTIFS(Screening!B2:B489,"Web of Science",Screening!N2:N489,"E5") -> 0 | E12: =B12+C12+D12 -> 18
A13: Retained after title/abstract screening | B13: =COUNTIFS(Screening!B2:B489,"Scopus",Screening!N2:N489,"INCLUDE") -> 178 | C13: =COUNTIFS(Screening!B2:B489,"IEEE Xplore",Screening!N2:N489,"INCLUDE") -> 53 | D13: =COUNTIFS(Screening!B2:B489,"Web of Science",Screening!N2:N489,"INCLUDE") -> 3 | E13: =B13+C13+D13 -> 234
A14: Check: screened = excluded + retained | B14: =B7-SUM(B8:B13) -> 0 | C14: =C7-SUM(C8:C13) -> 0 | D14: =D7-SUM(D8:D13) -> 0 | E14: =E7-SUM(E8:E13) -> 0 | F14: Must be 0

Sheet Protocol
A1: Databases | B1: Scopus (30 Sep 2026); IEEE Xplore and Web of Science Core Collection (1 Oct 2026); via UiTM EzAccess
A2: Scopus string | B2: TITLE-ABS-KEY ( "intrusion detection" ) AND TITLE-ABS-KEY ( "federated learning" OR "differential privacy" ) AND TITLE-ABS-KEY ( explainab* OR "SHAP" OR ontology OR "knowledge graph" ) AND PUBYEAR > 2018 AND PUBYEAR < 2027 AND ( LIMIT-TO ( LANGUAGE , "English" ) ) AND ( LIMIT-TO ( DOCTYPE , "ar" ) OR LIMIT-TO ( DOCTYPE , "cp" ) )
A3: IEEE Xplore string | B3: ("All Metadata":"intrusion detection") AND ("All Metadata":"federated learning" OR "All Metadata":"differential privacy") AND ("All Metadata":explainab* OR "All Metadata":SHAP OR "All Metadata":ontology OR "All Metadata":"knowledge graph"); Conferences and Journals
A4: Web of Science string | B4: TS=("intrusion detection") AND TS=("federated learning" OR "differential privacy") AND TS=(explainab* OR SHAP OR ontology OR "knowledge graph"); Article and Proceedings Paper; English
A5: Screening | B5: Keyword rules on title, abstract and author keywords, manual decisions for borderline records (E2) and manual checks of key records by the AI assistant. MUST be confirmed by the author in the yellow columns before reporting.
